<?xml version="1.0"?>
<robot xmlns:xacro="http://www.ros.org/wiki/xacro" name="simple_manipulator">
    <!-- Define Arguments -->
    <xacro:arg name="prefix" default="" />
    <xacro:arg name="use_gazebo" default="false" />

    <link name="world"></link>

    <!-- Base Link -->
    <link name="base_link">
        <visual>
            <geometry>
                <cylinder radius="0.1" length="0.2"/>
            </geometry>
            <material name="gray">
                <color rgba="0.5 0.5 0.5 1"/>
            </material>
        </visual>
        <collision>
            <geometry>
                <cylinder radius="0.1" length="0.2"/>
            </geometry>
        </collision>
        <inertial>
            <mass value="2.0"/>
            <origin xyz="0 0 0.1"/>
            <inertia ixx="0.1" iyy="0.1" izz="0.1" ixy="0" ixz="0" iyz="0"/>
        </inertial>
    </link>

    <joint name="joint1" type="revolute">
        <parent link="world"/>
        <child link="base_link"/>
        <origin xyz="0 0 0.1" rpy="0 0 0"/>
        <axis xyz="0 0 1"/>
        <limit lower="-3.1416" upper="3.1416" effort="5" velocity="2"/>
    </joint>

    <link name="link1">
        <visual>
            <origin xyz="0 0 0.25"/> 
            <geometry>
                <cylinder radius="0.05" length="0.5"/>
            </geometry>
            <material name="blue">
                <color rgba="0 0 1 1"/>
            </material>
        </visual>
        <collision>
            <origin xyz="0 0 0.25"/>
            <geometry>
                <cylinder radius="0.05" length="0.5"/>
            </geometry>
        </collision>
        <inertial>
            <mass value="1.0"/>
            <origin xyz="0 0 0.25"/> 
            <inertia ixx="0.05" iyy="0.05" izz="0.05" ixy="0" ixz="0" iyz="0"/>
        </inertial>
    </link>

    <joint name="joint2" type="revolute">
        <parent link="base_link"/>
        <child link="link1"/>
        <origin xyz="0 0 0.1" rpy="0 0 0"/> 
        <axis xyz="0 1 0"/>
        <limit lower="-1.5708" upper="1.5708" effort="5" velocity="2"/>
    </joint>

    <!-- ROS2 Control Section -->
    <ros2_control name="RobotSystemPositionManager" type="system">
        <hardware>
            <plugin>mock_components/GenericSystem</plugin>
        </hardware>
        <joint name="joint1">
            <command_interface name="position"/>
            <state_interface name="position"/>
            <state_interface name="velocity"/>
        </joint>
        <joint name="joint2">
            <command_interface name="position"/>
            <state_interface name="position"/>
            <state_interface name="velocity"/>
        </joint>
    </ros2_control>

    <!-- Transmission tags -->
    <transmission name="joint1_trans">
        <type>transmission_interface/SimpleTransmission</type>
        <joint name="joint1">
            <hardwareInterface>hardware_interface/PositionJointInterface</hardwareInterface>
        </joint>
        <actuator name="joint1_motor">
            <hardwareInterface>hardware_interface/PositionJointInterface</hardwareInterface>
        </actuator>
    </transmission>

    <transmission name="joint2_trans">
        <type>transmission_interface/SimpleTransmission</type>
        <joint name="joint2">
            <hardwareInterface>hardware_interface/PositionJointInterface</hardwareInterface>
        </joint>
        <actuator name="joint2_motor">
            <hardwareInterface>hardware_interface/PositionJointInterface</hardwareInterface>
        </actuator>
    </transmission>
</robot>
